Workbook

Sheet README_BENCHMARK
A1: Wilsify AI analysis benchmark
A2: Test IDs (TEST_001 ...) are permanent. Media files are named TEST_###.<ext>; file_rename_mapping.csv maps them back to the original names.
A3: Sources everywhere: GROUND_TRUTH, WILSIFY_AI, CHORD_AI, OTHER_REPO, CLAUDE. Prediction columns are never copied into ground truth.
A4: Ground truth values still to be provided: TO ENTER (key, capo), UNKNOWN (BPM), UNKNOWN / TO VERIFY (time signature). Do not replace them with a system prediction.
A5: Yellow cells are for you. Empty system columns mean that system has not been run yet.
A6: Capo: 0 = no capo, 1, 2, 3 ... = fret number (numbers, not text).
A7: Chord timestamps are stored in seconds as raw numbers. Different systems will have different timestamps; timing tolerance is applied later, not when entering data.
A8: Raw Chord is exactly what the source produced. Normalized Chord (e.g. Cmaj -> C, Amin -> Am) is filled later and never overwrites Raw Chord.
A9: Existing sheets 'Read me', 'Videos', 'Chords' and 'Wilsify said' are kept unchanged. They use the old IDs v01-v12; TEST_INDEX has a Legacy ID column linking them (v01 = TEST_001 ... v12 = TEST_012).
A10: Wilsify values in SONG_LEVEL_TRUTH and CHORD_TIMELINE come from the old 'Wilsify said' sheet (an earlier run of the app). They are not ground truth.

Sheet TEST_INDEX
A1: Test ID | B1: Current Filename | C1: Original Filename | D1: File Type | E1: Duration | F1: Description | G1: Status | H1: Notes | I1: Duration (sec) | J1: Legacy ID | K1: Video Size (WxH)
A2: TEST_001 | B2: TEST_001.mp4 | C2: InShot_20240603_124621068.mp4 | D2: MP4 | E2: 0:31 | F2: Boy playing acoustic guitar in a classroom | G2: READY | H2: Legacy ID v01 / 'Classroom Guitar'. Previous filename: v01_Classroom_Guitar.mp4 | I2: 30.77 | J2: v01 | K2: 712x1280
A3: TEST_002 | B3: TEST_002.mp4 | C3: Sunday brunch @thefishermanswharfmobor with @3_4_one.mp4 | D3: MP4 | E3: 2:17 | F3: Man in yellow tee playing keyboard, 'Goan music' brunch | G3: READY | H3: Legacy ID v02 / 'Keyboard Sunday Brunch'. Previous filename: v02_Keyboard_Sunday_Brunch.mp4 | I3: 137.37 | J3: v02 | K3: 720x1280
A4: TEST_003 | B4: TEST_003.mp4 | C4: Video-16744.mp4 | D4: MP4 | E4: 0:26 | F4: Group sitting in a living room, 'A generation that loves Jesus' | G4: READY | H4: Legacy ID v03 / 'Group Worship Singalong'. Previous filename: v03_Group_Worship_Singalong.mp4 | I4: 25.93 | J4: v03 | K4: 1276x720
A5: TEST_004 | B5: TEST_004.mp4 | C5: Video-22295.mp4 | D5: MP4 | E5: 1:37 | F5: Curly-haired guy, acoustic guitar, dark room | G5: READY | H5: Legacy ID v04 / 'Dark Room Acoustic'. Previous filename: v04_Dark_Room_Acoustic.mp4 | I5: 96.57 | J5: v04 | K5: 720x1280
A6: TEST_005 | B6: TEST_005.mp4 | C6: Video-23401.mp4 | D6: MP4 | E6: 0:31 | F6: Curly hair + glasses, singing 'bless the Lord oh my soul' | G6: READY | H6: Legacy ID v05 / 'Bless The Lord Acoustic'. Previous filename: v05_Bless_The_Lord_Acoustic.mp4 | I6: 31.3 | J6: v05 | K6: 720x1280
A7: TEST_006 | B7: TEST_006.mp4 | C7: Video-44412.mp4 | D7: MP4 | E7: 1:14 | F7: Two guys with acoustic guitars, teal room | G7: READY | H7: Legacy ID v06 / 'Duo Acoustic Jam'. Previous filename: v06_Duo_Acoustic_Jam.mp4 | I7: 73.74 | J7: v06 | K7: 720x960
A8: TEST_007 | B8: TEST_007.mp4 | C8: Video-45939.mp4 | D8: MP4 | E8: 0:32 | F8: Fingerstyle guitar with a tab shown on screen | G8: READY | H8: Legacy ID v07 / 'Fingerstyle Tab Lesson'. Previous filename: v07_Fingerstyle_Tab_Lesson.mp4 | I8: 32.46 | J8: v07 | K8: 720x1280
A9: TEST_008 | B9: TEST_008.mp4 | C9: Video-52398.mp4 | D9: MP4 | E9: 0:30 | F9: Man by a lake, 'I'm Not the Only One', Amaj7 | G9: READY | H9: Legacy ID v08 / 'Lake Not The Only One'. Previous filename: v08_Lake_Not_The_Only_One.mp4 | I9: 30.42 | J9: v08 | K9: 720x1280
A10: TEST_009 | B10: TEST_009.mp4 | C10: Video-57244.mp4 | D10: MP4 | E10: 1:09 | F10: Band jam with saxophone, 'Hips Don't Lie' | G10: READY | H10: Legacy ID v09 / 'Hips Dont Lie Sax Jam'. Previous filename: v09_Hips_Dont_Lie_Sax_Jam.mp4 | I10: 68.73 | J10: v09 | K10: 720x1280
A11: TEST_010 | B11: TEST_010.mp4 | C11: WhatsApp Video 2026-10-11 at 10.02.14 PM.mp4 | D11: MP4 | E11: 1:17 | F11: Guy on guitar + girl singing, @thestringprojectmusic | G11: READY | H11: Legacy ID v10 / 'String Project Duet'. Previous filename: v10_String_Project_Duet.mp4 | I11: 76.66 | J11: v10 | K11: 478x850
A12: TEST_011 | B12: TEST_011.mp4 | C12: WhatsApp Video 2026-10-11 at 8.42.45 PM.mp4 | D12: MP4 | E12: 1:37 | F12: Band, 'Novro mho'zo Portugala thavn Bombaim yetolo', @thesecretsauce_band | G12: READY | H12: Legacy ID v11 / 'Konkani Band Novro Portugala'. Previous filename: v11_Konkani_Band_Novro_Portugala.mp4 | I12: 97.24 | J12: v11 | K12: 478x850
A13: TEST_012 | B13: TEST_012.mp4 | C13: o começo dessa música é quase um trava língua... @alcioneamarrom.mp4 | D13: MP4 | E13: 0:41 | F13: Girl singing with acoustic guitar, Portuguese song | G13: READY | H13: Legacy ID v12 / 'Portuguese Girl Guitar'. Previous filename: v12_Portuguese_Girl_Guitar.mp4 | I13: 41.1 | J13: v12 | K13: 1080x1920
A14: TEST_013 | B14: TEST_013.mp4 | C14: WhatsApp Video 2026-10-16 at 2.50.19 PM.mp4 | D14: MP4 | E14: 1:18 | F14: NOT PROVIDED | G14: READY | H14: Added 2026-10-16 (WhatsApp). Description not provided yet. | I14: 78.03 | K14: 480x854
A15: TEST_014 | B15: TEST_014.mp4 | C15: WhatsApp Video 2026-10-16 at 2.50.28 PM.mp4 | D15: MP4 | E15: 0:44 | F15: NOT PROVIDED | G15: READY | H15: Added 2026-10-16 (WhatsApp). Description not provided yet. | I15: 43.58 | K15: 480x854
A16: TEST_015 | B16: TEST_015.mp4 | C16: WhatsApp Video 2026-10-16 at 2.51.08 PM.mp4 | D16: MP4 | E16: 0:29 | F16: NOT PROVIDED | G16: READY | H16: Added 2026-10-16 (WhatsApp). Description not provided yet. | I16: 29.04 | K16: 478x850
A17: TEST_016 | B17: TEST_016.mp4 | C17: WhatsApp Video 2026-10-16 at 2.51.09 PM.mp4 | D17: MP4 | E17: 1:12 | F17: NOT PROVIDED | G17: READY | H17: Added 2026-10-16 (WhatsApp). Description not provided yet. | I17: 72.45 | K17: 480x854
A18: TEST_017 | B18: TEST_017.mp4 | C18: WhatsApp Video 2026-10-16 at 2.51.09 PM (1).mp4 | D18: MP4 | E18: 2:14 | F18: NOT PROVIDED | G18: READY | H18: Added 2026-10-16 (WhatsApp). Description not provided yet. | I18: 133.68 | K18: 848x478
A19: TEST_018 | B19: TEST_018.mp4 | C19: WhatsApp Video 2026-10-16 at 2.51.10 PM.mp4 | D19: MP4 | E19: 1:14 | F19: NOT PROVIDED | G19: READY | H19: Added 2026-10-16 (WhatsApp). Description not provided yet. | I19: 74 | K19: 476x848
A20: TEST_019 | B20: TEST_019.mp4 | C20: WhatsApp Video 2026-10-16 at 2.51.10 PM (1).mp4 | D20: MP4 | E20: 1:23 | F20: NOT PROVIDED | G20: READY | H20: Added 2026-10-16 (WhatsApp). Description not provided yet. | I20: 83 | K20: 478x850
A21: TEST_020 | B21: TEST_020.mp4 | C21: WhatsApp Video 2026-10-16 at 2.51.10 PM (2).mp4 | D21: MP4 | E21: 1:41 | F21: NOT PROVIDED | G21: READY | H21: Added 2026-10-16 (WhatsApp). Description not provided yet. | I21: 100.65 | K21: 480x854

Sheet SONG_LEVEL_TRUTH
A1: Test ID | B1: Filename | C1: Duration (sec) | D1: Capo - Ground Truth / By Ear | E1: Capo - Wilsify AI | F1: Capo - Chord AI | G1: Capo - Other Repo | H1: Capo - Claude | I1: BPM - Ground Truth / By Ear | J1: BPM - Wilsify AI | K1: BPM - Chord AI | L1: BPM - Other Repo | M1: BPM - Claude | N1: Time Signature - Ground Truth / By Ear | O1: Time Signature - Wilsify AI | P1: Time Signature - Chord AI | Q1: Time Signature - Other Repo | R1: Time Signature - Claude | S1: Key - Ground Truth / Played | T1: Key - Wilsify AI | U1: Key - Chord AI | V1: Key - Other Repo | W1: Key - Claude | X1: Detected Tuning - Wilsify | Y1: Detected Tuning - Chord AI | Z1: Detected Tuning - Other Repo | AA1: Detected Tuning - Claude | AB1: Confidence - Wilsify | AC1: Confidence - Chord AI | AD1: Confidence - Other Repo | AE1: Confidence - Claude | AF1: Comments
A2: TEST_001 | B2: TEST_001.mp4 | C2: 30.77 | D2: 4 | E2: 4 | F2: 4 | G2: Not estimated | H2: Not estimated | I2: =IF(ISNUMBER(BPM_TRUTH!B2),BPM_TRUTH!B2,"UNKNOWN") | J2: 125 | K2: 125 | L2: 124 | M2: 123 | N2: =IF(OR(METER_TRUTH!B2="",LEFT(METER_TRUTH!B2,7)="UNKNOWN"),"UNKNOWN",METER_TRUTH!B2) | O2: 4/4 | P2: Not Shown | Q2: Not estimated | R2: 3/4 | S2: B (4th fret G) | T2: B (4th fret G) | U2: B (4th fret G) | V2: F# Major | W2: F# Major | X2: EADGBE | Y2: EADGBE | Z2: Not detected | AA2: Not detected (audio -5 cents vs A440) | AC2: not shown | AD2: key strength 0.88; tempo conf 1.91 | AE2: key votes 9/16 engines; tempo engines agreeing 4/4 | AF2: Wilsify = old 'Wilsify said' run (capo 'none' recorded as 0). First chords as detected: B G#m B C#7 F# C#7 B F# G#m C#7 F# A#m. Old 'Videos' sheet has Capo fret = 4 pre-filled; not treated as ground truth until you confirm.
A3: TEST_002 | B3: TEST_002.mp4 | C3: 137.37 | D3: 0 | E3: 0 | F3: 0 | G3: Not estimated | H3: Not estimated | I3: =IF(ISNUMBER(BPM_TRUTH!B3),BPM_TRUTH!B3,"UNKNOWN") | J3: 90 | K3: 180 | L3: 178 | M3: 89 | N3: =IF(OR(METER_TRUTH!B3="",LEFT(METER_TRUTH!B3,7)="UNKNOWN"),"UNKNOWN",METER_TRUTH!B3) | O3: 3/4 | P3: Not Shown | Q3: Not estimated | R3: AMBIGUOUS | S3: D Major | T3: D Major | U3: D Major | V3: D Major | W3: D Major | X3: EADGBE | Y3: EADGBE | Z3: Not detected | AA3: Not detected (audio -5 cents vs A440) | AC3: not shown | AD3: key strength 0.98; tempo conf 1.55 | AE3: key votes 13/16 engines; tempo engines agreeing 4/4 | AF3: Wilsify = old 'Wilsify said' run (capo 'none' recorded as 0). First chords as detected: G Bm7 G A G D G Bm F#m7 Em G A. Old 'Videos' sheet has Capo fret = 0 pre-filled; not treated as ground truth until you confirm.
A4: TEST_003 | B4: TEST_003.mp4 | C4: 25.93 | D4: 0 | E4: 0 | F4: 0 | G4: Not estimated | H4: Not estimated | I4: =IF(ISNUMBER(BPM_TRUTH!B4),BPM_TRUTH!B4,"UNKNOWN") | J4: 155 | K4: 79 | L4: 154 | M4: 152 | N4: =IF(OR(METER_TRUTH!B4="",LEFT(METER_TRUTH!B4,7)="UNKNOWN"),"UNKNOWN",METER_TRUTH!B4) | P4: Not Shown | Q4: Not estimated | R4: 4/4 | S4: Bb | T4: F Major | U4: Bb | V4: Bb Major | W4: A# Major | X4: EADGBE | Y4: EADGBE | Z4: Not detected | AA4: Not detected (audio +10 cents vs A440) | AC4: not shown | AD4: key strength 0.86; tempo conf 0.97 | AE4: key votes 13/16 engines; tempo engines agreeing 3/4 | AF4: Wilsify = old 'Wilsify said' run (capo 'none' recorded as 0). First chords as detected: F F7 D# Gm7 A# Dm Gm D# Gm7 D# A# Dm. Old 'Videos' sheet has Capo fret = 0 pre-filled; not treated as ground truth until you confirm.
A5: TEST_004 | B5: TEST_004.mp4 | C5: 96.57 | D5: 0 | E5: 0 | F5: 0 | G5: Not estimated | H5: Not estimated | I5: =IF(ISNUMBER(BPM_TRUTH!B5),BPM_TRUTH!B5,"UNKNOWN") | J5: 110 | K5: 111 | L5: 108 | M5: 108 | N5: =IF(OR(METER_TRUTH!B5="",LEFT(METER_TRUTH!B5,7)="UNKNOWN"),"UNKNOWN",METER_TRUTH!B5) | O5: 4/4 | P5: Not Shown | Q5: Not estimated | R5: 2/4 | S5: E Major | T5: E Major | U5: C#m | V5: E Major | W5: E Major | X5: EADGBE | Y5: EADGBE | Z5: Not detected | AA5: Not detected (audio +5 cents vs A440) | AC5: not shown | AD5: key strength 0.81; tempo conf 0.56 | AE5: key votes 16/16 engines; tempo engines agreeing 3/4 | AF5: Wilsify = old 'Wilsify said' run (capo 'none' recorded as 0). First chords as detected: E A F#m7 E A F#m A F#m Em E G#m E. Old 'Videos' sheet has Capo fret = 0 pre-filled; not treated as ground truth until you confirm.
A6: TEST_005 | B6: TEST_005.mp4 | C6: 31.3 | D6: 0 | E6: 0 | F6: 0 | G6: Not estimated | H6: Not estimated | I6: =IF(ISNUMBER(BPM_TRUTH!B6),BPM_TRUTH!B6,"UNKNOWN") | J6: 129 | K6: 66 | L6: 130 | M6: 129 | N6: =IF(OR(METER_TRUTH!B6="",LEFT(METER_TRUTH!B6,7)="UNKNOWN"),"UNKNOWN",METER_TRUTH!B6) | O6: 4/4 | P6: Not Shown | Q6: Not estimated | R6: AMBIGUOUS | S6: Eb | T6: Eb Major | U6: Eb | V6: Eb Major | W6: D# Major | X6: EADGBE | Y6: EADGBE | Z6: Not detected | AA6: Not detected (audio +5 cents vs A440) | AC6: not shown | AD6: key strength 0.95; tempo conf 0.89 | AE6: key votes 16/16 engines; tempo engines agreeing 4/4 | AF6: Wilsify = old 'Wilsify said' run (capo 'none' recorded as 0). First chords as detected: D# G# Cm7 D# A# D# Fm7 Cm7 D# A# D# G#. Old 'Videos' sheet has Capo fret = 0 pre-filled; not treated as ground truth until you confirm.
A7: TEST_006 | B7: TEST_006.mp4 | C7: 73.74 | D7: 0 | E7: 0 | F7: 0 | G7: Not estimated | H7: Not estimated | I7: =IF(ISNUMBER(BPM_TRUTH!B7),BPM_TRUTH!B7,"UNKNOWN") | J7: 105 | K7: 106 | L7: 104 | M7: 106 | N7: =IF(OR(METER_TRUTH!B7="",LEFT(METER_TRUTH!B7,7)="UNKNOWN"),"UNKNOWN",METER_TRUTH!B7) | O7: 4/4 | P7: Not Shown | Q7: Not estimated | R7: 12/8 | S7: G Major | T7: D Major | U7: G Major | V7: G Major | W7: G Major | X7: EADGBE | Y7: EADGBE | Z7: Not detected | AA7: Not detected (audio +10 cents vs A440) | AC7: not shown | AD7: key strength 0.9; tempo conf 2.54 | AE7: key votes 15/16 engines; tempo engines agreeing 4/4 | AF7: Wilsify = old 'Wilsify said' run (capo 'none' recorded as 0). First chords as detected: G Em G Em7 A7 G Em7 G Em D Em D. Old 'Videos' sheet has Capo fret = 0 pre-filled; not treated as ground truth until you confirm.
A8: TEST_007 | B8: TEST_007.mp4 | C8: 32.46 | D8: 0 | E8: 0 | F8: 0 | G8: Not estimated | H8: Not estimated | I8: =IF(ISNUMBER(BPM_TRUTH!B8),BPM_TRUTH!B8,"UNKNOWN") | J8: 120 | K8: 120 | L8: 118 | M8: 118 | N8: =IF(OR(METER_TRUTH!B8="",LEFT(METER_TRUTH!B8,7)="UNKNOWN"),"UNKNOWN",METER_TRUTH!B8) | O8: 4/4 | P8: Not Shown | Q8: Not estimated | R8: AMBIGUOUS | S8: E Minor | T8: E Minor | U8: E Minor | V8: E Minor | W8: E Minor | X8: EADGBE | Y8: EADGBE | Z8: Not detected | AA8: Not detected (audio -0 cents vs A440) | AC8: not shown | AD8: key strength 0.95; tempo conf 2.48 | AE8: key votes 13/16 engines; tempo engines agreeing 4/4 | AF8: Wilsify = old 'Wilsify said' run (capo 'none' recorded as 0). First chords as detected: E Em Em7 D G D Am G Bm Em B7 C. Old 'Videos' sheet has Capo fret = 0 pre-filled; not treated as ground truth until you confirm.
A9: TEST_008 | B9: TEST_008.mp4 | C9: 30.42 | D9: 0 | E9: 0 | F9: 0 | G9: Not estimated | H9: Not estimated | I9: =IF(ISNUMBER(BPM_TRUTH!B9),BPM_TRUTH!B9,"UNKNOWN") | J9: 99 | K9: 99 | L9: 99 | M9: 99 | N9: =IF(OR(METER_TRUTH!B9="",LEFT(METER_TRUTH!B9,7)="UNKNOWN"),"UNKNOWN",METER_TRUTH!B9) | O9: 4/3 | P9: Not Shown | Q9: Not estimated | R9: 2/4 | S9: E Major | T9: E Major | U9: E Major | V9: E Major | W9: E Major | X9: EADGBE | Y9: EADGBE | Z9: Not detected | AA9: Not detected (audio +10 cents vs A440) | AC9: not shown | AD9: key strength 0.9; tempo conf 2.34 | AE9: key votes 15/16 engines; tempo engines agreeing 4/4 | AF9: Wilsify = old 'Wilsify said' run (capo 'none' recorded as 0). First chords as detected: E C#m F#m A F#m E B7 E Am7 E Fm F#m. Old 'Videos' sheet has Capo fret = 0 pre-filled; not treated as ground truth until you confirm.
A10: TEST_009 | B10: TEST_009.mp4 | C10: 68.73 | D10: 0 | E10: 0 | F10: 0 | G10: Not estimated | H10: Not estimated | I10: =IF(ISNUMBER(BPM_TRUTH!B10),BPM_TRUTH!B10,"UNKNOWN") | J10: 104 | K10: 104 | L10: 104 | M10: 120 | N10: =IF(OR(METER_TRUTH!B10="",LEFT(METER_TRUTH!B10,7)="UNKNOWN"),"UNKNOWN",METER_TRUTH!B10) | O10: 4/4 | P10: Not Shown | Q10: Not estimated | R10: 4/4 | S10: Dm | T10: Dm | U10: Dm | V10: D Minor | W10: D Minor | X10: EADGBE | Y10: EADGBE | Z10: Not detected | AA10: Not detected (audio -0 cents vs A440) | AC10: not shown | AD10: key strength 0.95; tempo conf 3.36 | AE10: key votes 15/16 engines; tempo engines agreeing 0/4 | AF10: Wilsify = old 'Wilsify said' run (capo 'none' recorded as 0). First chords as detected: n/a. Old 'Videos' sheet has Capo fret = 0 pre-filled; not treated as ground truth until you confirm.
A11: TEST_010 | B11: TEST_010.mp4 | C11: 76.66 | D11: 0 | E11: 0 | F11: 0 | G11: Not estimated | H11: Not estimated | I11: =IF(ISNUMBER(BPM_TRUTH!B11),BPM_TRUTH!B11,"UNKNOWN") | J11: 113 | K11: 112 | L11: 112 | M11: 112 | N11: =IF(OR(METER_TRUTH!B11="",LEFT(METER_TRUTH!B11,7)="UNKNOWN"),"UNKNOWN",METER_TRUTH!B11) | O11: 4/4 | P11: Not Shown | Q11: Not estimated | R11: 6/8 | S11: Gb Major, F, A | T11: Gb Major | U11: B, Bb | V11: B Minor | W11: B Minor | X11: EADGBE | Y11: EADGBE | Z11: Not detected | AA11: Not detected (audio -0 cents vs A440) | AC11: not shown | AD11: key strength 0.66; tempo conf 0.85 | AE11: key votes 13/16 engines; tempo engines agreeing 4/4 | AF11: Wilsify = old 'Wilsify said' run (capo 'none' recorded as 0). First chords as detected: B C# G#m7 F# B G#m C# F# C# G#m7 C# F#. Old 'Videos' sheet has Capo fret = 0 pre-filled; not treated as ground truth until you confirm.
A12: TEST_011 | B12: TEST_011.mp4 | C12: 97.24 | D12: 0 | E12: 0 | F12: 0 | G12: Not estimated | H12: Not estimated | I12: =IF(ISNUMBER(BPM_TRUTH!B12),BPM_TRUTH!B12,"UNKNOWN") | J12: 122 | K12: 123 | L12: 122 | M12: 123 | N12: =IF(OR(METER_TRUTH!B12="",LEFT(METER_TRUTH!B12,7)="UNKNOWN"),"UNKNOWN",METER_TRUTH!B12) | O12: 4/4 | P12: Not Shown | Q12: Not estimated | R12: AMBIGUOUS | S12: G Major, E Major | T12: B Major | U12: G Major, E Major | V12: E Major | W12: E Major | X12: EADGBE | Y12: EADGBE | Z12: Not detected | AA12: Not detected (audio -0 cents vs A440) | AC12: not shown | AD12: key strength 0.83; tempo conf 3.22 | AE12: key votes 11/16 engines; tempo engines agreeing 4/4 | AF12: Wilsify = old 'Wilsify said' run (capo 'none' recorded as 0). First chords as detected: D7 E B Em E C#m D7 B D#m F#7 E F#7. Old 'Videos' sheet has Capo fret = 0 pre-filled; not treated as ground truth until you confirm.
A13: TEST_012 | B13: TEST_012.mp4 | C13: 41.1 | D13: 0 | E13: 0 | F13: 0 | G13: Not estimated | H13: Not estimated | I13: =IF(ISNUMBER(BPM_TRUTH!B13),BPM_TRUTH!B13,"UNKNOWN") | J13: 87 | K13: 67 | L13: 120 | M13: 117 | N13: =IF(OR(METER_TRUTH!B13="",LEFT(METER_TRUTH!B13,7)="UNKNOWN"),"UNKNOWN",METER_TRUTH!B13) | O13: 4/3 | P13: Not Shown | Q13: Not estimated | R13: AMBIGUOUS | S13: G# Minor | T13: G# Minor | U13: B Major | V13: Ab Minor | W13: G# Minor | X13: EADGBE | Y13: EADGBE | Z13: Not detected | AA13: Not detected (audio -5 cents vs A440) | AC13: not shown | AD13: key strength 0.86; tempo conf 0.42 | AE13: key votes 16/16 engines; tempo engines agreeing 3/4 | AF13: Wilsify = old 'Wilsify said' run (capo 'none' recorded as 0). First chords as detected: G#m F# C#m D# G#m C#m A D#m7 D# G#m F# C#m. Old 'Videos' sheet has Capo fret = 0 pre-filled; not treated as ground truth until you confirm.
A14: TEST_013 | B14: TEST_013.mp4 | C14: 78.03 | D14: 0 | E14: 0 | F14: 0 | G14: Not estimated | H14: Not estimated | I14: =IF(ISNUMBER(BPM_TRUTH!B14),BPM_TRUTH!B14,"UNKNOWN") | J14: 103 | K14: 103 | L14: 103 | M14: 103 | N14: =IF(OR(METER_TRUTH!B14="",LEFT(METER_TRUTH!B14,7)="UNKNOWN"),"UNKNOWN",METER_TRUTH!B14) | O14: 4/4 | P14: Not Shown | Q14: Not estimated | R14: 2/4 | S14: C Major | T14: C Major | U14: C Major | V14: C Major | W14: C Major | X14: EADGBE | Y14: EADGBE | Z14: Not detected | AA14: Not detected (audio -0 cents vs A440) | AC14: not shown | AD14: key strength 0.96; tempo conf 0.17 | AE14: key votes 16/16 engines; tempo engines agreeing 4/4
A15: TEST_014 | B15: TEST_014.mp4 | C15: 43.58 | D15: 0 | E15: 0 | F15: 0 | G15: Not estimated | H15: Not estimated | I15: =IF(ISNUMBER(BPM_TRUTH!B15),BPM_TRUTH!B15,"UNKNOWN") | J15: 99 | K15: 99 | L15: 100 | M15: 100 | N15: =IF(OR(METER_TRUTH!B15="",LEFT(METER_TRUTH!B15,7)="UNKNOWN"),"UNKNOWN",METER_TRUTH!B15) | O15: 4/4 | P15: Not Shown | Q15: Not estimated | R15: 2/4 | S15: Cm | T15: Cm | U15: Cm | V15: Eb Major | W15: D# Major | X15: EADGBE | Y15: EADGBE | Z15: Not detected | AA15: Not detected (audio -5 cents vs A440) | AC15: not shown | AD15: key strength 0.85; tempo conf 1.26 | AE15: key votes 14/16 engines; tempo engines agreeing 4/4
A16: TEST_015 | B16: TEST_015.mp4 | C16: 29.04 | D16: 0 | E16: 0 | F16: 0 | G16: Not estimated | H16: Not estimated | I16: =IF(ISNUMBER(BPM_TRUTH!B16),BPM_TRUTH!B16,"UNKNOWN") | J16: 114 | K16: 115 | L16: 112 | M16: 112 | N16: =IF(OR(METER_TRUTH!B16="",LEFT(METER_TRUTH!B16,7)="UNKNOWN"),"UNKNOWN",METER_TRUTH!B16) | O16: 4/4 | P16: Not Shown | Q16: Not estimated | R16: AMBIGUOUS | S16: C Major | T16: C Major | U16: C Major | V16: C Major | W16: C Major | X16: EADGBE | Y16: EADGBE | Z16: Not detected | AA16: Not detected (audio -0 cents vs A440) | AC16: not shown | AD16: key strength 0.89; tempo conf 1.93 | AE16: key votes 15/16 engines; tempo engines agreeing 4/4
A17: TEST_016 | B17: TEST_016.mp4 | C17: 72.45 | D17: 0 | E17: 0 | F17: 0 | G17: Not estimated | H17: Not estimated | I17: =IF(ISNUMBER(BPM_TRUTH!B17),BPM_TRUTH!B17,"UNKNOWN") | J17: 145 | K17: 122 | L17: 126 | M17: 124 | N17: =IF(OR(METER_TRUTH!B17="",LEFT(METER_TRUTH!B17,7)="UNKNOWN"),"UNKNOWN",METER_TRUTH!B17) | O17: 4/4 | P17: Not Shown | Q17: Not estimated | R17: 4/4 | S17: Am | T17: E Major | U17: C Major | V17: A Minor | W17: A Minor | X17: EADGBE | Y17: EADGBE | Z17: Not detected | AA17: Not detected (audio -0 cents vs A440) | AC17: not shown | AD17: key strength 0.85; tempo conf 0.19 | AE17: key votes 12/16 engines; tempo engines agreeing 4/4
A18: TEST_017 | B18: TEST_017.mp4 | C18: 133.68 | D18: 0 | E18: 0 | F18: 0 | G18: Not estimated | H18: Not estimated | I18: =IF(ISNUMBER(BPM_TRUTH!B18),BPM_TRUTH!B18,"UNKNOWN") | J18: 110 | K18: 73 | L18: 111 | M18: 117 | N18: =IF(OR(METER_TRUTH!B18="",LEFT(METER_TRUTH!B18,7)="UNKNOWN"),"UNKNOWN",METER_TRUTH!B18) | O18: 4/4 | P18: Not Shown | Q18: Not estimated | R18: 3/4 | S18: D Major | T18: D Major | U18: D Major | V18: D Major | W18: D Major | X18: EADGBE | Y18: EADGBE | Z18: Not detected | AA18: Not detected (audio -5 cents vs A440) | AC18: not shown | AD18: key strength 0.96; tempo conf -0.12 | AE18: key votes 16/16 engines; tempo engines agreeing 0/4
A19: TEST_018 | B19: TEST_018.mp4 | C19: 74 | D19: 0 | E19: 0 | F19: 0 | G19: Not estimated | H19: Not estimated | I19: =IF(ISNUMBER(BPM_TRUTH!B19),BPM_TRUTH!B19,"UNKNOWN") | J19: 121 | K19: 121 | L19: 120 | M19: 122 | N19: =IF(OR(METER_TRUTH!B19="",LEFT(METER_TRUTH!B19,7)="UNKNOWN"),"UNKNOWN",METER_TRUTH!B19) | O19: 4/4 | P19: Not Shown | Q19: Not estimated | R19: 4/4 | S19: G Major | T19: G Major | U19: G Major | V19: G Major | W19: G Major | X19: EADGBE | Y19: EADGBE | Z19: Not detected | AA19: Not detected (audio -10 cents vs A440) | AC19: not shown | AD19: key strength 0.94; tempo conf 1.11 | AE19: key votes 15/16 engines; tempo engines agreeing 4/4
A20: TEST_019 | B20: TEST_019.mp4 | C20: 83 | D20: 0 | E20: 0 | F20: 0 | G20: Not estimated | H20: Not estimated | I20: =IF(ISNUMBER(BPM_TRUTH!B20),BPM_TRUTH!B20,"UNKNOWN") | J20: 120 | K20: 120 | L20: 119 | M20: 121 | N20: =IF(OR(METER_TRUTH!B20="",LEFT(METER_TRUTH!B20,7)="UNKNOWN"),"UNKNOWN",METER_TRUTH!B20) | O20: 4/4 | P20: Not Shown | Q20: Not estimated | R20: 9/8 | S20: F Major | T20: F Major | U20: F Major | V20: F Major | W20: F Major | X20: EADGBE | Y20: EADGBE | Z20: Not detected | AA20: Not detected (audio +15 cents vs A440) | AC20: not shown | AD20: key strength 0.95; tempo conf 1.87 | AE20: key votes 16/16 engines; tempo engines agreeing 4/4
A21: TEST_020 | B21: TEST_020.mp4 | C21: 100.65 | D21: 0 | E21: 0 | F21: 0 | G21: Not estimated | H21: Not estimated | I21: =IF(ISNUMBER(BPM_TRUTH!B21),BPM_TRUTH!B21,"UNKNOWN") | J21: 114 | K21: 109 | L21: 114 | M21: 112 | N21: =IF(OR(METER_TRUTH!B21="",LEFT(METER_TRUTH!B21,7)="UNKNOWN"),"UNKNOWN",METER_TRUTH!B21) | O21: 4/4 | P21: Not Shown | Q21: Not estimated | R21: AMBIGUOUS | S21: E Major | T21: E Major | U21: C#m | V21: E Major | W21: E Major | X21: EADGBE | Y21: EADGBE | Z21: Not detected | AA21: Not detected (audio +5 cents vs A440) | AC21: not shown | AD21: key strength 0.81; tempo conf 0.38 | AE21: key votes 16/16 engines; tempo engines agreeing 3/4

Sheet BPM_TRUTH
A1: Test ID | B1: BPM Ground Truth | C1: BPM Ground Truth Method | D1: BPM Ground Truth Confidence | E1: Metronome BPM | F1: Manual Tap BPM | G1: Measured BPM | H1: Normalized BPM | I1: BPM - Wilsify AI | J1: BPM - Chord AI | K1: BPM - Other Repo | L1: BPM - Claude | M1: Wilsify BPM Error | N1: Chord AI BPM Error | O1: Other Repo BPM Error | P1: Claude BPM Error | Q1: Wilsify BPM Error % | R1: Chord AI BPM Error % | S1: Other Repo BPM Error % | T1: Claude BPM Error % | U1: Wilsify Tempo Relation | V1: Chord AI Tempo Relation | W1: Other Repo Tempo Relation | X1: Claude Tempo Relation | Y1: Half-Time Candidate | Z1: Double-Time Candidate | AA1: Tempo Confidence | AB1: Tempo Notes | AC1: Usable Beats | AD1: BPM Variation % | AE1: Raw Detector Values
A2: TEST_001 | C2: UNKNOWN - awaiting metronome setting / tap | D2: NONE | G2: 123.05 | H2: 123 | I2: =IFERROR(IF(INDEX(SONG_LEVEL_TRUTH!$J$2:$J$200,MATCH($A2,SONG_LEVEL_TRUTH!$A$2:$A$200,0))="","",INDEX(SONG_LEVEL_TRUTH!$J$2:$J$200,MATCH($A2,SONG_LEVEL_TRUTH!$A$2:$A$200,0))),"") | J2: =IFERROR(IF(INDEX(SONG_LEVEL_TRUTH!$K$2:$K$200,MATCH($A2,SONG_LEVEL_TRUTH!$A$2:$A$200,0))="","",INDEX(SONG_LEVEL_TRUTH!$K$2:$K$200,MATCH($A2,SONG_LEVEL_TRUTH!$A$2:$A$200,0))),"") | K2: =IFERROR(IF(INDEX(SONG_LEVEL_TRUTH!$L$2:$L$200,MATCH($A2,SONG_LEVEL_TRUTH!$A$2:$A$200,0))="","",INDEX(SONG_LEVEL_TRUTH!$L$2:$L$200,MATCH($A2,SONG_LEVEL_TRUTH!$A$2:$A$200,0))),"") | L2: =IFERROR(IF(INDEX(SONG_LEVEL_TRUTH!$M$2:$M$200,MATCH($A2,SONG_LEVEL_TRUTH!$A$2:$A$200,0))="","",INDEX(SONG_LEVEL_TRUTH!$M$2:$M$200,MATCH($A2,SONG_LEVEL_TRUTH!$A$2:$A$200,0))),"") | M2: =IF(ISNUMBER($B2),IF(ISNUMBER(I2),ABS(I2-$B2),"n/a"),"GT UNKNOWN") | N2: =IF(ISNUMBER($B2),IF(ISNUMBER(J2),ABS(J2-$B2),"n/a"),"GT UNKNOWN") | O2: =IF(ISNUMBER($B2),IF(ISNUMBER(K2),ABS(K2-$B2),"n/a"),"GT UNKNOWN") | P2: =IF(ISNUMBER($B2),IF(ISNUMBER(L2),ABS(L2-$B2),"n/a"),"GT UNKNOWN") | Q2: =IF(ISNUMBER($B2),IF(ISNUMBER(I2),ABS(I2-$B2)/$B2*100,"n/a"),"GT UNKNOWN") | R2: =IF(ISNUMBER($B2),IF(ISNUMBER(J2),ABS(J2-$B2)/$B2*100,"n/a"),"GT UNKNOWN") | S2: =IF(ISNUMBER($B2),IF(ISNUMBER(K2),ABS(K2-$B2)/$B2*100,"n/a"),"GT UNKNOWN") | T2: =IF(ISNUMBER($B2),IF(ISNUMBER(L2),ABS(L2-$B2)/$B2*100,"n/a"),"GT UNKNOWN") | U2: =IF(ISNUMBER($B2),IF(ISNUMBER(I2),IF(ABS(I2/$B2-1)<=0.03,"MATCH (within 3%)",IF(ABS(I2/$B2-2)<=0.06,"DOUBLE-TIME ERROR",IF(ABS(I2/$B2-0.5)<=0.03,"HALF-TIME ERROR","BPM ERROR"))),"n/a"),"GT UNKNOWN") | V2: =IF(ISNUMBER($B2),IF(ISNUMBER(J2),IF(ABS(J2/$B2-1)<=0.03,"MATCH (within 3%)",IF(ABS(J2/$B2-2)<=0.06,"DOUBLE-TIME ERROR",IF(ABS(J2/$B2-0.5)<=0.03,"HALF-TIME ERROR","BPM ERROR"))),"n/a"),"GT UNKNOWN") | W2: =IF(ISNUMBER($B2),IF(ISNUMBER(K2),IF(ABS(K2/$B2-1)<=0.03,"MATCH (within 3%)",IF(ABS(K2/$B2-2)<=0.06,"DOUBLE-TIME ERROR",IF(ABS(K2/$B2-0.5)<=0.03,"HALF-TIME ERROR","BPM ERROR"))),"n/a"),"GT UNKNOWN") | X2: =IF(ISNUMBER($B2),IF(ISNUMBER(L2),IF(ABS(L2/$B2-1)<=0.03,"MATCH (within 3%)",IF(ABS(L2/$B2-2)<=0.06,"DOUBLE-TIME ERROR",IF(ABS(L2/$B2-0.5)<=0.03,"HALF-TIME ERROR","BPM ERROR"))),"n/a"),"GT UNKNOWN") | Y2: 61.5 | Z2: 246.1 | AA2: MEDIUM | AB2: pulse support 5/6 methods; octave ambiguity possible - confirm by ear/metronome | AC2: 62 | AD2: 7.1 | AE2: ess_multifeature=123.6, ess_degara=123.6, lib_beat_track=123.0, tempogram=126.0, autocorr=123.0, ioi_hist=225.0
A3: TEST_002 | C3: UNKNOWN - awaiting metronome setting / tap | D3: NONE | G3: 178.21 | H3: 178.2 | I3: =IFERROR(IF(INDEX(SONG_LEVEL_TRUTH!$J$2:$J$200,MATCH($A3,SONG_LEVEL_TRUTH!$A$2:$A$200,0))="","",INDEX(SONG_LEVEL_TRUTH!$J$2:$J$200,MATCH($A3,SONG_LEVEL_TRUTH!$A$2:$A$200,0))),"") | J3: =IFERROR(IF(INDEX(SONG_LEVEL_TRUTH!$K$2:$K$200,MATCH($A3,SONG_LEVEL_TRUTH!$A$2:$A$200,0))="","",INDEX(SONG_LEVEL_TRUTH!$K$2:$K$200,MATCH($A3,SONG_LEVEL_TRUTH!$A$2:$A$200,0))),"") | K3: =IFERROR(IF(INDEX(SONG_LEVEL_TRUTH!$L$2:$L$200,MATCH($A3,SONG_LEVEL_TRUTH!$A$2:$A$200,0))="","",INDEX(SONG_LEVEL_TRUTH!$L$2:$L$200,MATCH($A3,SONG_LEVEL_TRUTH!$A$2:$A$200,0))),"") | L3: =IFERROR(IF(INDEX(SONG_LEVEL_TRUTH!$M$2:$M$200,MATCH($A3,SONG_LEVEL_TRUTH!$A$2:$A$200,0))="","",INDEX(SONG_LEVEL_TRUTH!$M$2:$M$200,MATCH($A3,SONG_LEVEL_TRUTH!$A$2:$A$200,0))),"") | M3: =IF(ISNUMBER($B3),IF(ISNUMBER(I3),ABS(I3-$B3),"n/a"),"GT UNKNOWN") | N3: =IF(ISNUMBER($B3),IF(ISNUMBER(J3),ABS(J3-$B3),"n/a"),"GT UNKNOWN") | O3: =IF(ISNUMBER($B3),IF(ISNUMBER(K3),ABS(K3-$B3),"n/a"),"GT UNKNOWN") | P3: =IF(ISNUMBER($B3),IF(ISNUMBER(L3),ABS(L3-$B3),"n/a"),"GT UNKNOWN") | Q3: =IF(ISNUMBER($B3),IF(ISNUMBER(I3),ABS(I3-$B3)/$B3*100,"n/a"),"GT UNKNOWN") | R3: =IF(ISNUMBER($B3),IF(ISNUMBER(J3),ABS(J3-$B3)/$B3*100,"n/a"),"GT UNKNOWN") | S3: =IF(ISNUMBER($B3),IF(ISNUMBER(K3),ABS(K3-$B3)/$B3*100,"n/a"),"GT UNKNOWN") | T3: =IF(ISNUMBER($B3),IF(ISNUMBER(L3),ABS(L3-$B3)/$B3*100,"n/a"),"GT UNKNOWN") | U3: =IF(ISNUMBER($B3),IF(ISNUMBER(I3),IF(ABS(I3/$B3-1)<=0.03,"MATCH (within 3%)",IF(ABS(I3/$B3-2)<=0.06,"DOUBLE-TIME ERROR",IF(ABS(I3/$B3-0.5)<=0.03,"HALF-TIME ERROR","BPM ERROR"))),"n/a"),"GT UNKNOWN") | V3: =IF(ISNUMBER($B3),IF(ISNUMBER(J3),IF(ABS(J3/$B3-1)<=0.03,"MATCH (within 3%)",IF(ABS(J3/$B3-2)<=0.06,"DOUBLE-TIME ERROR",IF(ABS(J3/$B3-0.5)<=0.03,"HALF-TIME ERROR","BPM ERROR"))),"n/a"),"GT UNKNOWN") | W3: =IF(ISNUMBER($B3),IF(ISNUMBER(K3),IF(ABS(K3/$B3-1)<=0.03,"MATCH (within 3%)",IF(ABS(K3/$B3-2)<=0.06,"DOUBLE-TIME ERROR",IF(ABS(K3/$B3-0.5)<=0.03,"HALF-TIME ERROR","BPM ERROR"))),"n/a"),"GT UNKNOWN") | X3: =IF(ISNUMBER($B3),IF(ISNUMBER(L3),IF(ABS(L3/$B3-1)<=0.03,"MATCH (within 3%)",IF(ABS(L3/$B3-2)<=0.06,"DOUBLE-TIME ERROR",IF(ABS(L3/$B3-0.5)<=0.03,"HALF-TIME ERROR","BPM ERROR"))),"n/a"),"GT UNKNOWN") | Y3: 89.1 | Z3: 356.4 | AA3: HIGH | AB3: pulse support 5/6 methods; octave ambiguity possible - confirm by ear/metronome | AC3: 410 | AD3: 0 | AE3: ess_multifeature=178.2, ess_degara=178.2, lib_beat_track=90.7, tempogram=178.2, autocorr=178.2, ioi_hist=179.0
A4: TEST_003 | C4: UNKNOWN - awaiting metronome setting / tap | D4: NONE | G4: 156.61 | H4: 147 | I4: =IFERROR(IF(INDEX(SONG_LEVEL_TRUTH!$J$2:$J$200,MATCH($A4,SONG_LEVEL_TRUTH!$A$2:$A$200,0))="","",INDEX(SONG_LEVEL_TRUTH!$J$2:$J$200,MATCH($A4,SONG_LEVEL_TRUTH!$A$2:$A$200,0))),"") | J4: =IFERROR(IF(INDEX(SONG_LEVEL_TRUTH!$K$2:$K$200,MATCH($A4,SONG_LEVEL_TRUTH!$A$2:$A$200,0))="","",INDEX(SONG_LEVEL_TRUTH!$K$2:$K$200,MATCH($A4,SONG_LEVEL_TRUTH!$A$2:$A$200,0))),"") | K4: =IFERROR(IF(INDEX(SONG_LEVEL_TRUTH!$L$2:$L$200,MATCH($A4,SONG_LEVEL_TRUTH!$A$2:$A$200,0))="","",INDEX(SONG_LEVEL_TRUTH!$L$2:$L$200,MATCH($A4,SONG_LEVEL_TRUTH!$A$2:$A$200,0))),"") | L4: =IFERROR(IF(INDEX(SONG_LEVEL_TRUTH!$M$2:$M$200,MATCH($A4,SONG_LEVEL_TRUTH!$A$2:$A$200,0))="","",INDEX(SONG_LEVEL_TRUTH!$M$2:$M$200,MATCH($A4,SONG_LEVEL_TRUTH!$A$2:$A$200,0))),"") | M4: =IF(ISNUMBER($B4),IF(ISNUMBER(I4),ABS(I4-$B4),"n/a"),"GT UNKNOWN") | N4: =IF(ISNUMBER($B4),IF(ISNUMBER(J4),ABS(J4-$B4),"n/a"),"GT UNKNOWN") | O4: =IF(ISNUMBER($B4),IF(ISNUMBER(K4),ABS(K4-$B4),"n/a"),"GT UNKNOWN") | P4: =IF(ISNUMBER($B4),IF(ISNUMBER(L4),ABS(L4-$B4),"n/a"),"GT UNKNOWN") | Q4: =IF(ISNUMBER($B4),IF(ISNUMBER(I4),ABS(I4-$B4)/$B4*100,"n/a"),"GT UNKNOWN") | R4: =IF(ISNUMBER($B4),IF(ISNUMBER(J4),ABS(J4-$B4)/$B4*100,"n/a"),"GT UNKNOWN") | S4: =IF(ISNUMBER($B4),IF(ISNUMBER(K4),ABS(K4-$B4)/$B4*100,"n/a"),"GT UNKNOWN") | T4: =IF(ISNUMBER($B4),IF(ISNUMBER(L4),ABS(L4-$B4)/$B4*100,"n/a"),"GT UNKNOWN") | U4: =IF(ISNUMBER($B4),IF(ISNUMBER(I4),IF(ABS(I4/$B4-1)<=0.03,"MATCH (within 3%)",IF(ABS(I4/$B4-2)<=0.06,"DOUBLE-TIME ERROR",IF(ABS(I4/$B4-0.5)<=0.03,"HALF-TIME ERROR","BPM ERROR"))),"n/a"),"GT UNKNOWN") | V4: =IF(ISNUMBER($B4),IF(ISNUMBER(J4),IF(ABS(J4/$B4-1)<=0.03,"MATCH (within 3%)",IF(ABS(J4/$B4-2)<=0.06,"DOUBLE-TIME ERROR",IF(ABS(J4/$B4-0.5)<=0.03,"HALF-TIME ERROR","BPM ERROR"))),"n/a"),"GT UNKNOWN") | W4: =IF(ISNUMBER($B4),IF(ISNUMBER(K4),IF(ABS(K4/$B4-1)<=0.03,"MATCH (within 3%)",IF(ABS(K4/$B4-2)<=0.06,"DOUBLE-TIME ERROR",IF(ABS(K4/$B4-0.5)<=0.03,"HALF-TIME ERROR","BPM ERROR"))),"n/a"),"GT UNKNOWN") | X4: =IF(ISNUMBER($B4),IF(ISNUMBER(L4),IF(ABS(L4/$B4-1)<=0.03,"MATCH (within 3%)",IF(ABS(L4/$B4-2)<=0.06,"DOUBLE-TIME ERROR",IF(ABS(L4/$B4-0.5)<=0.03,"HALF-TIME ERROR","BPM ERROR"))),"n/a"),"GT UNKNOWN") | Y4: 73.5 | Z4: 294 | AA4: LOW | AB4: methods disagree (octave/tempo ambiguity); pulse support 2/6 methods; octave ambiguity possible - confirm by ear/metronome | AC4: 66 | AD4: 4.5 | AE4: ess_multifeature=154.4, ess_degara=103.2, lib_beat_track=147.7, tempogram=156.6, autocorr=51.7, ioi_hist=147.0
A5: TEST_004 | C5: UNKNOWN - awaiting metronome setting / tap | D5: NONE | G5: 107.67 | H5: 110 | I5: =IFERROR(IF(INDEX(SONG_LEVEL_TRUTH!$J$2:$J$200,MATCH($A5,SONG_LEVEL_TRUTH!$A$2:$A$200,0))="","",INDEX(SONG_LEVEL_TRUTH!$J$2:$J$200,MATCH($A5,SONG_LEVEL_TRUTH!$A$2:$A$200,0))),"") | J5: =IFERROR(IF(INDEX(SONG_LEVEL_TRUTH!$K$2:$K$200,MATCH($A5,SONG_LEVEL_TRUTH!$A$2:$A$200,0))="","",INDEX(SONG_LEVEL_TRUTH!$K$2:$K$200,MATCH($A5,SONG_LEVEL_TRUTH!$A$2:$A$200,0))),"") | K5: =IFERROR(IF(INDEX(SONG_LEVEL_TRUTH!$L$2:$L$200,MATCH($A5,SONG_LEVEL_TRUTH!$A$2:$A$200,0))="","",INDEX(SONG_LEVEL_TRUTH!$L$2:$L$200,MATCH($A5,SONG_LEVEL_TRUTH!$A$2:$A$200,0))),"") | L5: =IFERROR(IF(INDEX(SONG_LEVEL_TRUTH!$M$2:$M$200,MATCH($A5,SONG_LEVEL_TRUTH!$A$2:$A$200,0))="","",INDEX(SONG_LEVEL_TRUTH!$M$2:$M$200,MATCH($A5,SONG_LEVEL_TRUTH!$A$2:$A$200,0))),"") | M5: =IF(ISNUMBER($B5),IF(ISNUMBER(I5),ABS(I5-$B5),"n/a"),"GT UNKNOWN") | N5: =IF(ISNUMBER($B5),IF(ISNUMBER(J5),ABS(J5-$B5),"n/a"),"GT UNKNOWN") | O5: =IF(ISNUMBER($B5),IF(ISNUMBER(K5),ABS(K5-$B5),"n/a"),"GT UNKNOWN") | P5: =IF(ISNUMBER($B5),IF(ISNUMBER(L5),ABS(L5-$B5),"n/a"),"GT UNKNOWN") | Q5: =IF(ISNUMBER($B5),IF(ISNUMBER(I5),ABS(I5-$B5)/$B5*100,"n/a"),"GT UNKNOWN") | R5: =IF(ISNUMBER($B5),IF(ISNUMBER(J5),ABS(J5-$B5)/$B5*100,"n/a"),"GT UNKNOWN") | S5: =IF(ISNUMBER($B5),IF(ISNUMBER(K5),ABS(K5-$B5)/$B5*100,"n/a"),"GT UNKNOWN") | T5: =IF(ISNUMBER($B5),IF(ISNUMBER(L5),ABS(L5-$B5)/$B5*100,"n/a"),"GT UNKNOWN") | U5: =IF(ISNUMBER($B5),IF(ISNUMBER(I5),IF(ABS(I5/$B5-1)<=0.03,"MATCH (within 3%)",IF(ABS(I5/$B5-2)<=0.06,"DOUBLE-TIME ERROR",IF(ABS(I5/$B5-0.5)<=0.03,"HALF-TIME ERROR","BPM ERROR"))),"n/a"),"GT UNKNOWN") | V5: =IF(ISNUMBER($B5),IF(ISNUMBER(J5),IF(ABS(J5/$B5-1)<=0.03,"MATCH (within 3%)",IF(ABS(J5/$B5-2)<=0.06,"DOUBLE-TIME ERROR",IF(ABS(J5/$B5-0.5)<=0.03,"HALF-TIME ERROR","BPM ERROR"))),"n/a"),"GT UNKNOWN") | W5: =IF(ISNUMBER($B5),IF(ISNUMBER(K5),IF(ABS(K5/$B5-1)<=0.03,"MATCH (within 3%)",IF(ABS(K5/$B5-2)<=0.06,"DOUBLE-TIME ERROR",IF(ABS(K5/$B5-0.5)<=0.03,"HALF-TIME ERROR","BPM ERROR"))),"n/a"),"GT UNKNOWN") | X5: =IF(ISNUMBER($B5),IF(ISNUMBER(L5),IF(ABS(L5/$B5-1)<=0.03,"MATCH (within 3%)",IF(ABS(L5/$B5-2)<=0.06,"DOUBLE-TIME ERROR",IF(ABS(L5/$B5-0.5)<=0.03,"HALF-TIME ERROR","BPM ERROR"))),"n/a"),"GT UNKNOWN") | Y5: 55 | Z5: 219.9 | AA5: MEDIUM | AB5: pulse support 3/6 methods; octave ambiguity possible - confirm by ear/metronome | AC5: 170 | AD5: 6.2 | AE5: ess_multifeature=108.4, ess_degara=113.4, lib_beat_track=110.0, tempogram=215.3, autocorr=53.8, ioi_hist=179.0
A6: TEST_005 | C6: UNKNOWN - awaiting metronome setting / tap | D6: NONE | G6: 129.2 | H6: 129.2 | I6: =IFERROR(IF(INDEX(SONG_LEVEL_TRUTH!$J$2:$J$200,MATCH($A6,SONG_LEVEL_TRUTH!$A$2:$A$200,0))="","",INDEX(SONG_LEVEL_TRUTH!$J$2:$J$200,MATCH($A6,SONG_LEVEL_TRUTH!$A$2:$A$200,0))),"") | J6: =IFERROR(IF(INDEX(SONG_LEVEL_TRUTH!$K$2:$K$200,MATCH($A6,SONG_LEVEL_TRUTH!$A$2:$A$200,0))="","",INDEX(SONG_LEVEL_TRUTH!$K$2:$K$200,MATCH($A6,SONG_LEVEL_TRUTH!$A$2:$A$200,0))),"") | K6: =IFERROR(IF(INDEX(SONG_LEVEL_TRUTH!$L$2:$L$200,MATCH($A6,SONG_LEVEL_TRUTH!$A$2:$A$200,0))="","",INDEX(SONG_LEVEL_TRUTH!$L$2:$L$200,MATCH($A6,SONG_LEVEL_TRUTH!$A$2:$A$200,0))),"") | L6: =IFERROR(IF(INDEX(SONG_LEVEL_TRUTH!$M$2:$M$200,MATCH($A6,SONG_LEVEL_TRUTH!$A$2:$A$200,0))="","",INDEX(SONG_LEVEL_TRUTH!$M$2:$M$200,MATCH($A6,SONG_LEVEL_TRUTH!$A$2:$A$200,0))),"") | M6: =IF(ISNUMBER($B6),IF(ISNUMBER(I6),ABS(I6-$B6),"n/a"),"GT UNKNOWN") | N6: =IF(ISNUMBER($B6),IF(ISNUMBER(J6),ABS(J6-$B6),"n/a"),"GT UNKNOWN") | O6: =IF(ISNUMBER($B6),IF(ISNUMBER(K6),ABS(K6-$B6),"n/a"),"GT UNKNOWN") | P6: =IF(ISNUMBER($B6),IF(ISNUMBER(L6),ABS(L6-$B6),"n/a"),"GT UNKNOWN") | Q6: =IF(ISNUMBER($B6),IF(ISNUMBER(I6),ABS(I6-$B6)/$B6*100,"n/a"),"GT UNKNOWN") | R6: =IF(ISNUMBER($B6),IF(ISNUMBER(J6),ABS(J6-$B6)/$B6*100,"n/a"),"GT UNKNOWN") | S6: =IF(ISNUMBER($B6),IF(ISNUMBER(K6),ABS(K6-$B6)/$B6*100,"n/a"),"GT UNKNOWN") | T6: =IF(ISNUMBER($B6),IF(ISNUMBER(L6),ABS(L6-$B6)/$B6*100,"n/a"),"GT UNKNOWN") | U6: =IF(ISNUMBER($B6),IF(ISNUMBER(I6),IF(ABS(I6/$B6-1)<=0.03,"MATCH (within 3%)",IF(ABS(I6/$B6-2)<=0.06,"DOUBLE-TIME ERROR",IF(ABS(I6/$B6-0.5)<=0.03,"HALF-TIME ERROR","BPM ERROR"))),"n/a"),"GT UNKNOWN") | V6: =IF(ISNUMBER($B6),IF(ISNUMBER(J6),IF(ABS(J6/$B6-1)<=0.03,"MATCH (within 3%)",IF(ABS(J6/$B6-2)<=0.06,"DOUBLE-TIME ERROR",IF(ABS(J6/$B6-0.5)<=0.03,"HALF-TIME ERROR","BPM ERROR"))),"n/a"),"GT UNKNOWN") | W6: =IF(ISNUMBER($B6),IF(ISNUMBER(K6),IF(ABS(K6/$B6-1)<=0.03,"MATCH (within 3%)",IF(ABS(K6/$B6-2)<=0.06,"DOUBLE-TIME ERROR",IF(ABS(K6/$B6-0.5)<=0.03,"HALF-TIME ERROR","BPM ERROR"))),"n/a"),"GT UNKNOWN") | X6: =IF(ISNUMBER($B6),IF(ISNUMBER(L6),IF(ABS(L6/$B6-1)<=0.03,"MATCH (within 3%)",IF(ABS(L6/$B6-2)<=0.06,"DOUBLE-TIME ERROR",IF(ABS(L6/$B6-0.5)<=0.03,"HALF-TIME ERROR","BPM ERROR"))),"n/a"),"GT UNKNOWN") | Y6: 64.6 | Z6: 258.4 | AA6: HIGH | AB6: pulse support 5/6 methods; octave ambiguity possible - confirm by ear/metronome | AC6: 66 | AD6: 3.7 | AE6: ess_multifeature=129.5, ess_degara=131.3, lib_beat_track=129.2, tempogram=129.2, autocorr=63.8, ioi_hist=133.0
A7: TEST_006 | C7: UNKNOWN - awaiting metronome setting / tap | D7: NONE | G7: 103.36 | H7: 105.2 | I7: =IFERROR(IF(INDEX(SONG_LEVEL_TRUTH!$J$2:$J$200,MATCH($A7,SONG_LEVEL_TRUTH!$A$2:$A$200,0))="","",INDEX(SONG_LEVEL_TRUTH!$J$2:$J$200,MATCH($A7,SONG_LEVEL_TRUTH!$A$2:$A$200,0))),"") | J7: =IFERROR(IF(INDEX(SONG_LEVEL_TRUTH!$K$2:$K$200,MATCH($A7,SONG_LEVEL_TRUTH!$A$2:$A$200,0))="","",INDEX(SONG_LEVEL_TRUTH!$K$2:$K$200,MATCH($A7,SONG_LEVEL_TRUTH!$A$2:$A$200,0))),"") | K7: =IFERROR(IF(INDEX(SONG_LEVEL_TRUTH!$L$2:$L$200,MATCH($A7,SONG_LEVEL_TRUTH!$A$2:$A$200,0))="","",INDEX(SONG_LEVEL_TRUTH!$L$2:$L$200,MATCH($A7,SONG_LEVEL_TRUTH!$A$2:$A$200,0))),"") | L7: =IFERROR(IF(INDEX(SONG_LEVEL_TRUTH!$M$2:$M$200,MATCH($A7,SONG_LEVEL_TRUTH!$A$2:$A$200,0))="","",INDEX(SONG_LEVEL_TRUTH!$M$2:$M$200,MATCH($A7,SONG_LEVEL_TRUTH!$A$2:$A$200,0))),"") | M7: =IF(ISNUMBER($B7),IF(ISNUMBER(I7),ABS(I7-$B7),"n/a"),"GT UNKNOWN") | N7: =IF(ISNUMBER($B7),IF(ISNUMBER(J7),ABS(J7-$B7),"n/a"),"GT UNKNOWN") | O7: =IF(ISNUMBER($B7),IF(ISNUMBER(K7),ABS(K7-$B7),"n/a"),"GT UNKNOWN") | P7: =IF(ISNUMBER($B7),IF(ISNUMBER(L7),ABS(L7-$B7),"n/a"),"GT UNKNOWN") | Q7: =IF(ISNUMBER($B7),IF(ISNUMBER(I7),ABS(I7-$B7)/$B7*100,"n/a"),"GT UNKNOWN") | R7: =IF(ISNUMBER($B7),IF(ISNUMBER(J7),ABS(J7-$B7)/$B7*100,"n/a"),"GT UNKNOWN") | S7: =IF(ISNUMBER($B7),IF(ISNUMBER(K7),ABS(K7-$B7)/$B7*100,"n/a"),"GT UNKNOWN") | T7: =IF(ISNUMBER($B7),IF(ISNUMBER(L7),ABS(L7-$B7)/$B7*100,"n/a"),"GT UNKNOWN") | U7: =IF(ISNUMBER($B7),IF(ISNUMBER(I7),IF(ABS(I7/$B7-1)<=0.03,"MATCH (within 3%)",IF(ABS(I7/$B7-2)<=0.06,"DOUBLE-TIME ERROR",IF(ABS(I7/$B7-0.5)<=0.03,"HALF-TIME ERROR","BPM ERROR"))),"n/a"),"GT UNKNOWN") | V7: =IF(ISNUMBER($B7),IF(ISNUMBER(J7),IF(ABS(J7/$B7-1)<=0.03,"MATCH (within 3%)",IF(ABS(J7/$B7-2)<=0.06,"DOUBLE-TIME ERROR",IF(ABS(J7/$B7-0.5)<=0.03,"HALF-TIME ERROR","BPM ERROR"))),"n/a"),"GT UNKNOWN") | W7: =IF(ISNUMBER($B7),IF(ISNUMBER(K7),IF(ABS(K7/$B7-1)<=0.03,"MATCH (within 3%)",IF(ABS(K7/$B7-2)<=0.06,"DOUBLE-TIME ERROR",IF(ABS(K7/$B7-0.5)<=0.03,"HALF-TIME ERROR","BPM ERROR"))),"n/a"),"GT UNKNOWN") | X7: =IF(ISNUMBER($B7),IF(ISNUMBER(L7),IF(ABS(L7/$B7-1)<=0.03,"MATCH (within 3%)",IF(ABS(L7/$B7-2)<=0.06,"DOUBLE-TIME ERROR",IF(ABS(L7/$B7-0.5)<=0.03,"HALF-TIME ERROR","BPM ERROR"))),"n/a"),"GT UNKNOWN") | Y7: 52.6 | Z7: 210.3 | AA7: HIGH | AB7: pulse support 5/6 methods; octave ambiguity possible - confirm by ear/metronome | AC7: 127 | AD7: 3 | AE7: ess_multifeature=104.5, ess_degara=105.2, lib_beat_track=105.5, tempogram=105.5, autocorr=105.5, ioi_hist=179.0
A8: TEST_007 | C8: UNKNOWN - awaiting metronome setting / tap | D8: NONE | G8: 118.8 | H8: 117 | I8: =IFERROR(IF(INDEX(SONG_LEVEL_TRUTH!$J$2:$J$200,MATCH($A8,SONG_LEVEL_TRUTH!$A$2:$A$200,0))="","",INDEX(SONG_LEVEL_TRUTH!$J$2:$J$200,MATCH($A8,SONG_LEVEL_TRUTH!$A$2:$A$200,0))),"") | J8: =IFERROR(IF(INDEX(SONG_LEVEL_TRUTH!$K$2:$K$200,MATCH($A8,SONG_LEVEL_TRUTH!$A$2:$A$200,0))="","",INDEX(SONG_LEVEL_TRUTH!$K$2:$K$200,MATCH($A8,SONG_LEVEL_TRUTH!$A$2:$A$200,0))),"") | K8: =IFERROR(IF(INDEX(SONG_LEVEL_TRUTH!$L$2:$L$200,MATCH($A8,SONG_LEVEL_TRUTH!$A$2:$A$200,0))="","",INDEX(SONG_LEVEL_TRUTH!$L$2:$L$200,MATCH($A8,SONG_LEVEL_TRUTH!$A$2:$A$200,0))),"") | L8: =IFERROR(IF(INDEX(SONG_LEVEL_TRUTH!$M$2:$M$200,MATCH($A8,SONG_LEVEL_TRUTH!$A$2:$A$200,0))="","",INDEX(SONG_LEVEL_TRUTH!$M$2:$M$200,MATCH($A8,SONG_LEVEL_TRUTH!$A$2:$A$200,0))),"") | M8: =IF(ISNUMBER($B8),IF(ISNUMBER(I8),ABS(I8-$B8),"n/a"),"GT UNKNOWN") | N8: =IF(ISNUMBER($B8),IF(ISNUMBER(J8),ABS(J8-$B8),"n/a"),"GT UNKNOWN") | O8: =IF(ISNUMBER($B8),IF(ISNUMBER(K8),ABS(K8-$B8),"n/a"),"GT UNKNOWN") | P8: =IF(ISNUMBER($B8),IF(ISNUMBER(L8),ABS(L8-$B8),"n/a"),"GT UNKNOWN") | Q8: =IF(ISNUMBER($B8),IF(ISNUMBER(I8),ABS(I8-$B8)/$B8*100,"n/a"),"GT UNKNOWN") | R8: =IF(ISNUMBER($B8),IF(ISNUMBER(J8),ABS(J8-$B8)/$B8*100,"n/a"),"GT UNKNOWN") | S8: =IF(ISNUMBER($B8),IF(ISNUMBER(K8),ABS(K8-$B8)/$B8*100,"n/a"),"GT UNKNOWN") | T8: =IF(ISNUMBER($B8),IF(ISNUMBER(L8),ABS(L8-$B8)/$B8*100,"n/a"),"GT UNKNOWN") | U8: =IF(ISNUMBER($B8),IF(ISNUMBER(I8),IF(ABS(I8/$B8-1)<=0.03,"MATCH (within 3%)",IF(ABS(I8/$B8-2)<=0.06,"DOUBLE-TIME ERROR",IF(ABS(I8/$B8-0.5)<=0.03,"HALF-TIME ERROR","BPM ERROR"))),"n/a"),"GT UNKNOWN") | V8: =IF(ISNUMBER($B8),IF(ISNUMBER(J8),IF(ABS(J8/$B8-1)<=0.03,"MATCH (within 3%)",IF(ABS(J8/$B8-2)<=0.06,"DOUBLE-TIME ERROR",IF(ABS(J8/$B8-0.5)<=0.03,"HALF-TIME ERROR","BPM ERROR"))),"n/a"),"GT UNKNOWN") | W8: =IF(ISNUMBER($B8),IF(ISNUMBER(K8),IF(ABS(K8/$B8-1)<=0.03,"MATCH (within 3%)",IF(ABS(K8/$B8-2)<=0.06,"DOUBLE-TIME ERROR",IF(ABS(K8/$B8-0.5)<=0.03,"HALF-TIME ERROR","BPM ERROR"))),"n/a"),"GT UNKNOWN") | X8: =IF(ISNUMBER($B8),IF(ISNUMBER(L8),IF(ABS(L8/$B8-1)<=0.03,"MATCH (within 3%)",IF(ABS(L8/$B8-2)<=0.06,"DOUBLE-TIME ERROR",IF(ABS(L8/$B8-0.5)<=0.03,"HALF-TIME ERROR","BPM ERROR"))),"n/a"),"GT UNKNOWN") | Y8: 58.5 | Z8: 234 | AA8: HIGH | AB8: pulse support 6/6 methods; octave ambiguity possible - confirm by ear/metronome | AC8: 63 | AD8: 3.4 | AE8: ess_multifeature=117.9, ess_degara=118.0, lib_beat_track=120.2, tempogram=120.2, autocorr=120.2, ioi_hist=117.0
A9: TEST_008 | C9: UNKNOWN - awaiting metronome setting / tap | D9: NONE | G9: 99.38 | H9: 99.5 | I9: =IFERROR(IF(INDEX(SONG_LEVEL_TRUTH!$J$2:$J$200,MATCH($A9,SONG_LEVEL_TRUTH!$A$2:$A$200,0))="","",INDEX(SONG_LEVEL_TRUTH!$J$2:$J$200,MATCH($A9,SONG_LEVEL_TRUTH!$A$2:$A$200,0))),"") | J9: =IFERROR(IF(INDEX(SONG_LEVEL_TRUTH!$K$2:$K$200,MATCH($A9,SONG_LEVEL_TRUTH!$A$2:$A$200,0))="","",INDEX(SONG_LEVEL_TRUTH!$K$2:$K$200,MATCH($A9,SONG_LEVEL_TRUTH!$A$2:$A$200,0))),"") | K9: =IFERROR(IF(INDEX(SONG_LEVEL_TRUTH!$L$2:$L$200,MATCH($A9,SONG_LEVEL_TRUTH!$A$2:$A$200,0))="","",INDEX(SONG_LEVEL_TRUTH!$L$2:$L$200,MATCH($A9,SONG_LEVEL_TRUTH!$A$2:$A$200,0))),"") | L9: =IFERROR(IF(INDEX(SONG_LEVEL_TRUTH!$M$2:$M$200,MATCH($A9,SONG_LEVEL_TRUTH!$A$2:$A$200,0))="","",INDEX(SONG_LEVEL_TRUTH!$M$2:$M$200,MATCH($A9,SONG_LEVEL_TRUTH!$A$2:$A$200,0))),"") | M9: =IF(ISNUMBER($B9),IF(ISNUMBER(I9),ABS(I9-$B9),"n/a"),"GT UNKNOWN") | N9: =IF(ISNUMBER($B9),IF(ISNUMBER(J9),ABS(J9-$B9),"n/a"),"GT UNKNOWN") | O9: =IF(ISNUMBER($B9),IF(ISNUMBER(K9),ABS(K9-$B9),"n/a"),"GT UNKNOWN") | P9: =IF(ISNUMBER($B9),IF(ISNUMBER(L9),ABS(L9-$B9),"n/a"),"GT UNKNOWN") | Q9: =IF(ISNUMBER($B9),IF(ISNUMBER(I9),ABS(I9-$B9)/$B9*100,"n/a"),"GT UNKNOWN") | R9: =IF(ISNUMBER($B9),IF(ISNUMBER(J9),ABS(J9-$B9)/$B9*100,"n/a"),"GT UNKNOWN") | S9: =IF(ISNUMBER($B9),IF(ISNUMBER(K9),ABS(K9-$B9)/$B9*100,"n/a"),"GT UNKNOWN") | T9: =IF(ISNUMBER($B9),IF(ISNUMBER(L9),ABS(L9-$B9)/$B9*100,"n/a"),"GT UNKNOWN") | U9: =IF(ISNUMBER($B9),IF(ISNUMBER(I9),IF(ABS(I9/$B9-1)<=0.03,"MATCH (within 3%)",IF(ABS(I9/$B9-2)<=0.06,"DOUBLE-TIME ERROR",IF(ABS(I9/$B9-0.5)<=0.03,"HALF-TIME ERROR","BPM ERROR"))),"n/a"),"GT UNKNOWN") | V9: =IF(ISNUMBER($B9),IF(ISNUMBER(J9),IF(ABS(J9/$B9-1)<=0.03,"MATCH (within 3%)",IF(ABS(J9/$B9-2)<=0.06,"DOUBLE-TIME ERROR",IF(ABS(J9/$B9-0.5)<=0.03,"HALF-TIME ERROR","BPM ERROR"))),"n/a"),"GT UNKNOWN") | W9: =IF(ISNUMBER($B9),IF(ISNUMBER(K9),IF(ABS(K9/$B9-1)<=0.03,"MATCH (within 3%)",IF(ABS(K9/$B9-2)<=0.06,"DOUBLE-TIME ERROR",IF(ABS(K9/$B9-0.5)<=0.03,"HALF-TIME ERROR","BPM ERROR"))),"n/a"),"GT UNKNOWN") | X9: =IF(ISNUMBER($B9),IF(ISNUMBER(L9),IF(ABS(L9/$B9-1)<=0.03,"MATCH (within 3%)",IF(ABS(L9/$B9-2)<=0.06,"DOUBLE-TIME ERROR",IF(ABS(L9/$B9-0.5)<=0.03,"HALF-TIME ERROR","BPM ERROR"))),"n/a"),"GT UNKNOWN") | Y9: 49.8 | Z9: 199 | AA9: MEDIUM | AB9: pulse support 3/6 methods; octave ambiguity possible - confirm by ear/metronome | AC9: 49 | AD9: 2.9 | AE9: ess_multifeature=98.8, ess_degara=98.9, lib_beat_track=99.4, tempogram=198.8, autocorr=198.8, ioi_hist=199.0
A10: TEST_009 | C10: UNKNOWN - awaiting metronome setting / tap | D10: NONE | G10: 103.36 | H10: 104.4 | I10: =IFERROR(IF(INDEX(SONG_LEVEL_TRUTH!$J$2:$J$200,MATCH($A10,SONG_LEVEL_TRUTH!$A$2:$A$200,0))="","",INDEX(SONG_LEVEL_TRUTH!$J$2:$J$200,MATCH($A10,SONG_LEVEL_TRUTH!$A$2:$A$200,0))),"") | J10: =IFERROR(IF(INDEX(SONG_LEVEL_TRUTH!$K$2:$K$200,MATCH($A10,SONG_LEVEL_TRUTH!$A$2:$A$200,0))="","",INDEX(SONG_LEVEL_TRUTH!$K$2:$K$200,MATCH($A10,SONG_LEVEL_TRUTH!$A$2:$A$200,0))),"") | K10: =IFERROR(IF(INDEX(SONG_LEVEL_TRUTH!$L$2:$L$200,MATCH($A10,SONG_LEVEL_TRUTH!$A$2:$A$200,0))="","",INDEX(SONG_LEVEL_TRUTH!$L$2:$L$200,MATCH($A10,SONG_LEVEL_TRUTH!$A$2:$A$200,0))),"") | L10: =IFERROR(IF(INDEX(SONG_LEVEL_TRUTH!$M$2:$M$200,MATCH($A10,SONG_LEVEL_TRUTH!$A$2:$A$200,0))="","",INDEX(SONG_LEVEL_TRUTH!$M$2:$M$200,MATCH($A10,SONG_LEVEL_TRUTH!$A$2:$A$200,0))),"") | M10: =IF(ISNUMBER($B10),IF(ISNUMBER(I10),ABS(I10-$B10),"n/a"),"GT UNKNOWN") | N10: =IF(ISNUMBER($B10),IF(ISNUMBER(J10),ABS(J10-$B10),"n/a"),"GT UNKNOWN") | O10: =IF(ISNUMBER($B10),IF(ISNUMBER(K10),ABS(K10-$B10),"n/a"),"GT UNKNOWN") | P10: =IF(ISNUMBER($B10),IF(ISNUMBER(L10),ABS(L10-$B10),"n/a"),"GT UNKNOWN") | Q10: =IF(ISNUMBER($B10),IF(ISNUMBER(I10),ABS(I10-$B10)/$B10*100,"n/a"),"GT UNKNOWN") | R10: =IF(ISNUMBER($B10),IF(ISNUMBER(J10),ABS(J10-$B10)/$B10*100,"n/a"),"GT UNKNOWN") | S10: =IF(ISNUMBER($B10),IF(ISNUMBER(K10),ABS(K10-$B10)/$B10*100,"n/a"),"GT UNKNOWN") | T10: =IF(ISNUMBER($B10),IF(ISNUMBER(L10),ABS(L10-$B10)/$B10*100,"n/a"),"GT UNKNOWN") | U10: =IF(ISNUMBER($B10),IF(ISNUMBER(I10),IF(ABS(I10/$B10-1)<=0.03,"MATCH (within 3%)",IF(ABS(I10/$B10-2)<=0.06,"DOUBLE-TIME ERROR",IF(ABS(I10/$B10-0.5)<=0.03,"HALF-TIME ERROR","BPM ERROR"))),"n/a"),"GT UNKNOWN") | V10: =IF(ISNUMBER($B10),IF(ISNUMBER(J10),IF(ABS(J10/$B10-1)<=0.03,"MATCH (within 3%)",IF(ABS(J10/$B10-2)<=0.06,"DOUBLE-TIME ERROR",IF(ABS(J10/$B10-0.5)<=0.03,"HALF-TIME ERROR","BPM ERROR"))),"n/a"),"GT UNKNOWN") | W10: =IF(ISNUMBER($B10),IF(ISNUMBER(K10),IF(ABS(K10/$B10-1)<=0.03,"MATCH (within 3%)",IF(ABS(K10/$B10-2)<=0.06,"DOUBLE-TIME ERROR",IF(ABS(K10/$B10-0.5)<=0.03,"HALF-TIME ERROR","BPM ERROR"))),"n/a"),"GT UNKNOWN") | X10: =IF(ISNUMBER($B10),IF(ISNUMBER(L10),IF(ABS(L10/$B10-1)<=0.03,"MATCH (within 3%)",IF(ABS(L10/$B10-2)<=0.06,"DOUBLE-TIME ERROR",IF(ABS(L10/$B10-0.5)<=0.03,"HALF-TIME ERROR","BPM ERROR"))),"n/a"),"GT UNKNOWN") | Y10: 52.2 | Z10: 208.8 | AA10: LOW | AB10: methods disagree (octave/tempo ambiguity); pulse support 2/6 methods; octave ambiguity possible - confirm by ear/metronome | AC10: 118 | AD10: 0 | AE10: ess_multifeature=104.0, ess_degara=104.0, lib_beat_track=139.7, tempogram=206.7, autocorr=52.2, ioi_hist=207.0
A11: TEST_010 | C11: UNKNOWN - awaiting metronome setting / tap | D11: NONE | G11: 112.35 | H11: 111.6 | I11: =IFERROR(IF(INDEX(SONG_LEVEL_TRUTH!$J$2:$J$200,MATCH($A11,SONG_LEVEL_TRUTH!$A$2:$A$200,0))="","",INDEX(SONG_LEVEL_TRUTH!$J$2:$J$200,MATCH($A11,SONG_LEVEL_TRUTH!$A$2:$A$200,0))),"") | J11: =IFERROR(IF(INDEX(SONG_LEVEL_TRUTH!$K$2:$K$200,MATCH($A11,SONG_LEVEL_TRUTH!$A$2:$A$200,0))="","",INDEX(SONG_LEVEL_TRUTH!$K$2:$K$200,MATCH($A11,SONG_LEVEL_TRUTH!$A$2:$A$200,0))),"") | K11: =IFERROR(IF(INDEX(SONG_LEVEL_TRUTH!$L$2:$L$200,MATCH($A11,SONG_LEVEL_TRUTH!$A$2:$A$200,0))="","",INDEX(SONG_LEVEL_TRUTH!$L$2:$L$200,MATCH($A11,SONG_LEVEL_TRUTH!$A$2:$A$200,0))),"") | L11: =IFERROR(IF(INDEX(SONG_LEVEL_TRUTH!$M$2:$M$200,MATCH($A11,SONG_LEVEL_TRUTH!$A$2:$A$200,0))="","",INDEX(SONG_LEVEL_TRUTH!$M$2:$M$200,MATCH($A11,SONG_LEVEL_TRUTH!$A$2:$A$200,0))),"") | M11: =IF(ISNUMBER($B11),IF(ISNUMBER(I11),ABS(I11-$B11),"n/a"),"GT UNKNOWN") | N11: =IF(ISNUMBER($B11),IF(ISNUMBER(J11),ABS(J11-$B11),"n/a"),"GT UNKNOWN") | O11: =IF(ISNUMBER($B11),IF(ISNUMBER(K11),ABS(K11-$B11),"n/a"),"GT UNKNOWN") | P11: =IF(ISNUMBER($B11),IF(ISNUMBER(L11),ABS(L11-$B11),"n/a"),"GT UNKNOWN") | Q11: =IF(ISNUMBER($B11),IF(ISNUMBER(I11),ABS(I11-$B11)/$B11*100,"n/a"),"GT UNKNOWN") | R11: =IF(ISNUMBER($B11),IF(ISNUMBER(J11),ABS(J11-$B11)/$B11*100,"n/a"),"GT UNKNOWN") | S11: =IF(ISNUMBER($B11),IF(ISNUMBER(K11),ABS(K11-$B11)/$B11*100,"n/a"),"GT UNKNOWN") | T11: =IF(ISNUMBER($B11),IF(ISNUMBER(L11),ABS(L11-$B11)/$B11*100,"n/a"),"GT UNKNOWN") | U11: =IF(ISNUMBER($B11),IF(ISNUMBER(I11),IF(ABS(I11/$B11-1)<=0.03,"MATCH (within 3%)",IF(ABS(I11/$B11-2)<=0.06,"DOUBLE-TIME ERROR",IF(ABS(I11/$B11-0.5)<=0.03,"HALF-TIME ERROR","BPM ERROR"))),"n/a"),"GT UNKNOWN") | V11: =IF(ISNUMBER($B11),IF(ISNUMBER(J11),IF(ABS(J11/$B11-1)<=0.03,"MATCH (within 3%)",IF(ABS(J11/$B11-2)<=0.06,"DOUBLE-TIME ERROR",IF(ABS(J11/$B11-0.5)<=0.03,"HALF-TIME ERROR","BPM ERROR"))),"n/a"),"GT UNKNOWN") | W11: =IF(ISNUMBER($B11),IF(ISNUMBER(K11),IF(ABS(K11/$B11-1)<=0.03,"MATCH (within 3%)",IF(ABS(K11/$B11-2)<=0.06,"DOUBLE-TIME ERROR",IF(ABS(K11/$B11-0.5)<=0.03,"HALF-TIME ERROR","BPM ERROR"))),"n/a"),"GT UNKNOWN") | X11: =IF(ISNUMBER($B11),IF(ISNUMBER(L11),IF(ABS(L11/$B11-1)<=0.03,"MATCH (within 3%)",IF(ABS(L11/$B11-2)<=0.06,"DOUBLE-TIME ERROR",IF(ABS(L11/$B11-0.5)<=0.03,"HALF-TIME ERROR","BPM ERROR"))),"n/a"),"GT UNKNOWN") | Y11: 55.8 | Z11: 223.3 | AA11: HIGH | AB11: pulse support 5/6 methods; octave ambiguity possible - confirm by ear/metronome | AC11: 143 | AD11: 3.2 | AE11: ess_multifeature=111.6, ess_degara=112.0, lib_beat_track=112.3, tempogram=112.3, autocorr=112.3, ioi_hist=173.0
A12: TEST_011 | C12: UNKNOWN - awaiting metronome setting / tap | D12: NONE | G12: 123.05 | H12: 121.6 | I12: =IFERROR(IF(INDEX(SONG_LEVEL_TRUTH!$J$2:$J$200,MATCH($A12,SONG_LEVEL_TRUTH!$A$2:$A$200,0))="","",INDEX(SONG_LEVEL_TRUTH!$J$2:$J$200,MATCH($A12,SONG_LEVEL_TRUTH!$A$2:$A$200,0))),"") | J12: =IFERROR(IF(INDEX(SONG_LEVEL_TRUTH!$K$2:$K$200,MATCH($A12,SONG_LEVEL_TRUTH!$A$2:$A$200,0))="","",INDEX(SONG_LEVEL_TRUTH!$K$2:$K$200,MATCH($A12,SONG_LEVEL_TRUTH!$A$2:$A$200,0))),"") | K12: =IFERROR(IF(INDEX(SONG_LEVEL_TRUTH!$L$2:$L$200,MATCH($A12,SONG_LEVEL_TRUTH!$A$2:$A$200,0))="","",INDEX(SONG_LEVEL_TRUTH!$L$2:$L$200,MATCH($A12,SONG_LEVEL_TRUTH!$A$2:$A$200,0))),"") | L12: =IFERROR(IF(INDEX(SONG_LEVEL_TRUTH!$M$2:$M$200,MATCH($A12,SONG_LEVEL_TRUTH!$A$2:$A$200,0))="","",INDEX(SONG_LEVEL_TRUTH!$M$2:$M$200,MATCH($A12,SONG_LEVEL_TRUTH!$A$2:$A$200,0))),"") | M12: =IF(ISNUMBER($B12),IF(ISNUMBER(I12),ABS(I12-$B12),"n/a"),"GT UNKNOWN") | N12: =IF(ISNUMBER($B12),IF(ISNUMBER(J12),ABS(J12-$B12),"n/a"),"GT UNKNOWN") | O12: =IF(ISNUMBER($B12),IF(ISNUMBER(K12),ABS(K12-$B12),"n/a"),"GT UNKNOWN") | P12: =IF(ISNUMBER($B12),IF(ISNUMBER(L12),ABS(L12-$B12),"n/a"),"GT UNKNOWN") | Q12: =IF(ISNUMBER($B12),IF(ISNUMBER(I12),ABS(I12-$B12)/$B12*100,"n/a"),"GT UNKNOWN") | R12: =IF(ISNUMBER($B12),IF(ISNUMBER(J12),ABS(J12-$B12)/$B12*100,"n/a"),"GT UNKNOWN") | S12: =IF(ISNUMBER($B12),IF(ISNUMBER(K12),ABS(K12-$B12)/$B12*100,"n/a"),"GT UNKNOWN") | T12: =IF(ISNUMBER($B12),IF(ISNUMBER(L12),ABS(L12-$B12)/$B12*100,"n/a"),"GT UNKNOWN") | U12: =IF(ISNUMBER($B12),IF(ISNUMBER(I12),IF(ABS(I12/$B12-1)<=0.03,"MATCH (within 3%)",IF(ABS(I12/$B12-2)<=0.06,"DOUBLE-TIME ERROR",IF(ABS(I12/$B12-0.5)<=0.03,"HALF-TIME ERROR","BPM ERROR"))),"n/a"),"GT UNKNOWN") | V12: =IF(ISNUMBER($B12),IF(ISNUMBER(J12),IF(ABS(J12/$B12-1)<=0.03,"MATCH (within 3%)",IF(ABS(J12/$B12-2)<=0.06,"DOUBLE-TIME ERROR",IF(ABS(J12/$B12-0.5)<=0.03,"HALF-TIME ERROR","BPM ERROR"))),"n/a"),"GT UNKNOWN") | W12: =IF(ISNUMBER($B12),IF(ISNUMBER(K12),IF(ABS(K12/$B12-1)<=0.03,"MATCH (within 3%)",IF(ABS(K12/$B12-2)<=0.06,"DOUBLE-TIME ERROR",IF(ABS(K12/$B12-0.5)<=0.03,"HALF-TIME ERROR","BPM ERROR"))),"n/a"),"GT UNKNOWN") | X12: =IF(ISNUMBER($B12),IF(ISNUMBER(L12),IF(ABS(L12/$B12-1)<=0.03,"MATCH (within 3%)",IF(ABS(L12/$B12-2)<=0.06,"DOUBLE-TIME ERROR",IF(ABS(L12/$B12-0.5)<=0.03,"HALF-TIME ERROR","BPM ERROR"))),"n/a"),"GT UNKNOWN") | Y12: 60.8 | Z12: 243.2 | AA12: HIGH | AB12: pulse support 4/6 methods; octave ambiguity possible - confirm by ear/metronome | AC12: 196 | AD12: 0 | AE12: ess_multifeature=122.1, ess_degara=122.1, lib_beat_track=123.0, tempogram=123.0, autocorr=60.8, ioi_hist=247.0
A13: TEST_012 | C13: UNKNOWN - awaiting metronome setting / tap | D13: NONE | G13: 117.45 | H13: 117.5 | I13: =IFERROR(IF(INDEX(SONG_LEVEL_TRUTH!$J$2:$J$200,MATCH($A13,SONG_LEVEL_TRUTH!$A$2:$A$200,0))="","",INDEX(SONG_LEVEL_TRUTH!$J$2:$J$200,MATCH($A13,SONG_LEVEL_TRUTH!$A$2:$A$200,0))),"") | J13: =IFERROR(IF(INDEX(SONG_LEVEL_TRUTH!$K$2:$K$200,MATCH($A13,SONG_LEVEL_TRUTH!$A$2:$A$200,0))="","",INDEX(SONG_LEVEL_TRUTH!$K$2:$K$200,MATCH($A13,SONG_LEVEL_TRUTH!$A$2:$A$200,0))),"") | K13: =IFERROR(IF(INDEX(SONG_LEVEL_TRUTH!$L$2:$L$200,MATCH($A13,SONG_LEVEL_TRUTH!$A$2:$A$200,0))="","",INDEX(SONG_LEVEL_TRUTH!$L$2:$L$200,MATCH($A13,SONG_LEVEL_TRUTH!$A$2:$A$200,0))),"") | L13: =IFERROR(IF(INDEX(SONG_LEVEL_TRUTH!$M$2:$M$200,MATCH($A13,SONG_LEVEL_TRUTH!$A$2:$A$200,0))="","",INDEX(SONG_LEVEL_TRUTH!$M$2:$M$200,MATCH($A13,SONG_LEVEL_TRUTH!$A$2:$A$200,0))),"") | M13: =IF(ISNUMBER($B13),IF(ISNUMBER(I13),ABS(I13-$B13),"n/a"),"GT UNKNOWN") | N13: =IF(ISNUMBER($B13),IF(ISNUMBER(J13),ABS(J13-$B13),"n/a"),"GT UNKNOWN") | O13: =IF(ISNUMBER($B13),IF(ISNUMBER(K13),ABS(K13-$B13),"n/a"),"GT UNKNOWN") | P13: =IF(ISNUMBER($B13),IF(ISNUMBER(L13),ABS(L13-$B13),"n/a"),"GT UNKNOWN") | Q13: =IF(ISNUMBER($B13),IF(ISNUMBER(I13),ABS(I13-$B13)/$B13*100,"n/a"),"GT UNKNOWN") | R13: =IF(ISNUMBER($B13),IF(ISNUMBER(J13),ABS(J13-$B13)/$B13*100,"n/a"),"GT UNKNOWN") | S13: =IF(ISNUMBER($B13),IF(ISNUMBER(K13),ABS(K13-$B13)/$B13*100,"n/a"),"GT UNKNOWN") | T13: =IF(ISNUMBER($B13),IF(ISNUMBER(L13),ABS(L13-$B13)/$B13*100,"n/a"),"GT UNKNOWN") | U13: =IF(ISNUMBER($B13),IF(ISNUMBER(I13),IF(ABS(I13/$B13-1)<=0.03,"MATCH (within 3%)",IF(ABS(I13/$B13-2)<=0.06,"DOUBLE-TIME ERROR",IF(ABS(I13/$B13-0.5)<=0.03,"HALF-TIME ERROR","BPM ERROR"))),"n/a"),"GT UNKNOWN") | V13: =IF(ISNUMBER($B13),IF(ISNUMBER(J13),IF(ABS(J13/$B13-1)<=0.03,"MATCH (within 3%)",IF(ABS(J13/$B13-2)<=0.06,"DOUBLE-TIME ERROR",IF(ABS(J13/$B13-0.5)<=0.03,"HALF-TIME ERROR","BPM ERROR"))),"n/a"),"GT UNKNOWN") | W13: =IF(ISNUMBER($B13),IF(ISNUMBER(K13),IF(ABS(K13/$B13-1)<=0.03,"MATCH (within 3%)",IF(ABS(K13/$B13-2)<=0.06,"DOUBLE-TIME ERROR",IF(ABS(K13/$B13-0.5)<=0.03,"HALF-TIME ERROR","BPM ERROR"))),"n/a"),"GT UNKNOWN") | X13: =IF(ISNUMBER($B13),IF(ISNUMBER(L13),IF(ABS(L13/$B13-1)<=0.03,"MATCH (within 3%)",IF(ABS(L13/$B13-2)<=0.06,"DOUBLE-TIME ERROR",IF(ABS(L13/$B13-0.5)<=0.03,"HALF-TIME ERROR","BPM ERROR"))),"n/a"),"GT UNKNOWN") | Y13: 58.7 | Z13: 234.9 | AA13: MEDIUM | AB13: pulse support 3/6 methods; octave ambiguity possible - confirm by ear/metronome | AC13: 79 | AD13: 3.4 | AE13: ess_multifeature=119.7, ess_degara=89.2, lib_beat_track=117.5, tempogram=184.6, autocorr=117.5, ioi_hist=191.0
... A21: TEST_020 | C21: UNKNOWN - awaiting metronome setting / tap | D21: NONE | G21: 109.96 | H21: 112.3 | I21: =IFERROR(IF(INDEX(SONG_LEVEL_TRUTH!$J$2:$J$200,MATCH($A21,SONG_LEVEL_TRUTH!$A$2:$A$200,0))="","",INDEX(SONG_LEVEL_TRUTH!$J$2:$J$200,MATCH($A21,SONG_LEVEL_TRUTH!$A$2:$A$200,0))),"") | J21: =IFERROR(IF(INDEX(SONG_LEVEL_TRUTH!$K$2:$K$200,MATCH($A21,SONG_LEVEL_TRUTH!$A$2:$A$200,0))="","",INDEX(SONG_LEVEL_TRUTH!$K$2:$K$200,MATCH($A21,SONG_LEVEL_TRUTH!$A$2:$A$200,0))),"") | K21: =IFERROR(IF(INDEX(SONG_LEVEL_TRUTH!$L$2:$L$200,MATCH($A21,SONG_LEVEL_TRUTH!$A$2:$A$200,0))="","",INDEX(SONG_LEVEL_TRUTH!$L$2:$L$200,MATCH($A21,SONG_LEVEL_TRUTH!$A$2:$A$200,0))),"") | L21: =IFERROR(IF(INDEX(SONG_LEVEL_TRUTH!$M$2:$M$200,MATCH($A21,SONG_LEVEL_TRUTH!$A$2:$A$200,0))="","",INDEX(SONG_LEVEL_TRUTH!$M$2:$M$200,MATCH($A21,SONG_LEVEL_TRUTH!$A$2:$A$200,0))),"") | M21: =IF(ISNUMBER($B21),IF(ISNUMBER(I21),ABS(I21-$B21),"n/a"),"GT UNKNOWN") | N21: =IF(ISNUMBER($B21),IF(ISNUMBER(J21),ABS(J21-$B21),"n/a"),"GT UNKNOWN") | O21: =IF(ISNUMBER($B21),IF(ISNUMBER(K21),ABS(K21-$B21),"n/a"),"GT UNKNOWN") | P21: =IF(ISNUMBER($B21),IF(ISNUMBER(L21),ABS(L21-$B21),"n/a"),"GT UNKNOWN") | Q21: =IF(ISNUMBER($B21),IF(ISNUMBER(I21),ABS(I21-$B21)/$B21*100,"n/a"),"GT UNKNOWN") | R21: =IF(ISNUMBER($B21),IF(ISNUMBER(J21),ABS(J21-$B21)/$B21*100,"n/a"),"GT UNKNOWN") | S21: =IF(ISNUMBER($B21),IF(ISNUMBER(K21),ABS(K21-$B21)/$B21*100,"n/a"),"GT UNKNOWN") | T21: =IF(ISNUMBER($B21),IF(ISNUMBER(L21),ABS(L21-$B21)/$B21*100,"n/a"),"GT UNKNOWN") | U21: =IF(ISNUMBER($B21),IF(ISNUMBER(I21),IF(ABS(I21/$B21-1)<=0.03,"MATCH (within 3%)",IF(ABS(I21/$B21-2)<=0.06,"DOUBLE-TIME ERROR",IF(ABS(I21/$B21-0.5)<=0.03,"HALF-TIME ERROR","BPM ERROR"))),"n/a"),"GT UNKNOWN") | V21: =IF(ISNUMBER($B21),IF(ISNUMBER(J21),IF(ABS(J21/$B21-1)<=0.03,"MATCH (within 3%)",IF(ABS(J21/$B21-2)<=0.06,"DOUBLE-TIME ERROR",IF(ABS(J21/$B21-0.5)<=0.03,"HALF-TIME ERROR","BPM ERROR"))),"n/a"),"GT UNKNOWN") | W21: =IF(ISNUMBER($B21),IF(ISNUMBER(K21),IF(ABS(K21/$B21-1)<=0.03,"MATCH (within 3%)",IF(ABS(K21/$B21-2)<=0.06,"DOUBLE-TIME ERROR",IF(ABS(K21/$B21-0.5)<=0.03,"HALF-TIME ERROR","BPM ERROR"))),"n/a"),"GT UNKNOWN") | X21: =IF(ISNUMBER($B21),IF(ISNUMBER(L21),IF(ABS(L21/$B21-1)<=0.03,"MATCH (within 3%)",IF(ABS(L21/$B21-2)<=0.06,"DOUBLE-TIME ERROR",IF(ABS(L21/$B21-0.5)<=0.03,"HALF-TIME ERROR","BPM ERROR"))),"n/a"),"GT UNKNOWN") | Y21: 56.2 | Z21: 224.7 | AA21: LOW | AB21: methods disagree (octave/tempo ambiguity); pulse support 2/6 methods; octave ambiguity possible - confirm by ear/metronome | AC21: 183 | AD21: 6.3 | AE21: ess_multifeature=113.7, ess_degara=105.7, lib_beat_track=112.3, tempogram=215.3, autocorr=53.8, ioi_hist=91.0

Sheet METER_TRUTH
A1: Test ID | B1: Time Signature Ground Truth | C1: Time Signature Ground Truth Method | D1: Metronome Time Signature | E1: Time Signature - Wilsify AI | F1: Time Signature - Chord AI | G1: Time Signature - Other Repo | H1: Time Signature - Claude | I1: Wilsify Correct? | J1: Chord AI Correct? | K1: Other Repo Correct? | L1: Claude Correct? | M1: Detected Beat Grouping | N1: Detected Subdivision | O1: Meter Confidence | P1: Meter Notes
A2: TEST_001 | C2: UNKNOWN - awaiting metronome setting / by ear | E2: =IFERROR(IF(INDEX(SONG_LEVEL_TRUTH!$O$2:$O$200,MATCH($A2,SONG_LEVEL_TRUTH!$A$2:$A$200,0))="","",INDEX(SONG_LEVEL_TRUTH!$O$2:$O$200,MATCH($A2,SONG_LEVEL_TRUTH!$A$2:$A$200,0))),"") | F2: =IFERROR(IF(INDEX(SONG_LEVEL_TRUTH!$P$2:$P$200,MATCH($A2,SONG_LEVEL_TRUTH!$A$2:$A$200,0))="","",INDEX(SONG_LEVEL_TRUTH!$P$2:$P$200,MATCH($A2,SONG_LEVEL_TRUTH!$A$2:$A$200,0))),"") | G2: =IFERROR(IF(INDEX(SONG_LEVEL_TRUTH!$Q$2:$Q$200,MATCH($A2,SONG_LEVEL_TRUTH!$A$2:$A$200,0))="","",INDEX(SONG_LEVEL_TRUTH!$Q$2:$Q$200,MATCH($A2,SONG_LEVEL_TRUTH!$A$2:$A$200,0))),"") | H2: =IFERROR(IF(INDEX(SONG_LEVEL_TRUTH!$R$2:$R$200,MATCH($A2,SONG_LEVEL_TRUTH!$A$2:$A$200,0))="","",INDEX(SONG_LEVEL_TRUTH!$R$2:$R$200,MATCH($A2,SONG_LEVEL_TRUTH!$A$2:$A$200,0))),"") | I2: =IF(OR($B2="",LEFT($B2,7)="UNKNOWN"),"GT UNKNOWN",IF(TRIM(E2)=TRIM($B2),"YES","NO")) | J2: =IF(OR($B2="",LEFT($B2,7)="UNKNOWN"),"GT UNKNOWN",IF(TRIM(F2)=TRIM($B2),"YES","NO")) | K2: =IF(OR($B2="",LEFT($B2,7)="UNKNOWN"),"GT UNKNOWN",IF(TRIM(G2)=TRIM($B2),"YES","NO")) | L2: =IF(OR($B2="",LEFT($B2,7)="UNKNOWN"),"GT UNKNOWN",IF(TRIM(H2)=TRIM($B2),"YES","NO")) | M2: 3 | N2: 2 | O2: MEDIUM | P2: accent period=3 beats (score 1.00, margin 0.46); triplet-vs-duple subdiv ratio 0.98; 61 beats | guitar-only: accent evidence is weak, treat as a hypothesis
